<?xml version="1.0"?>
<robot name="xMatePro7">

  <material name="white"><color rgba="1.0 1.0 1.0 1.0"/></material>

  <link name="world"/>
  <joint name="fixed" type="fixed">
    <parent link="world"/>
    <child link="xMatePro7_base"/>
  </joint>

  <link name="xMatePro7_base">
    <visual>
      <geometry><mesh filename="package://rokae_description/meshes/xMateER7p/visual/xMatePro7_base.stl" scale="0.001 0.001 0.001"/></geometry>
      <origin rpy="0 0 0" xyz="0.0 0.0 0.0"/><material name="white"/>
    </visual>
    <collision>
      <geometry><mesh filename="package://rokae_description/meshes/xMateER7p/collision/xMatePro7_base.stl" scale="0.001 0.001 0.001"/></geometry>
      <origin rpy="0 0 0" xyz="0.0 0.0 0.0"/>
    </collision>
    <inertial>
      <mass value="5.48267"/>
      <inertia ixx="0.016" ixy="0" ixz="0" iyy="0.016" iyz="0" izz="0.012"/>
      <origin rpy="0 0 0" xyz="-0.0183 0 0.067"/> 
    </inertial>
  </link>
  
  <joint name="joint1" type="revolute">
    <parent link="xMatePro7_base"/>
    <child link="xMatePro7_link1"/>
    <limit effort="300" lower="-3.0527" upper="3.0527" velocity="10"/>
    <axis xyz="0 0 1"/>
    <origin rpy="0 0 0" xyz="0 0 0"/>
  </joint>
 
  <link name="xMatePro7_link1">
    <visual>
      <geometry><mesh filename="package://rokae_description/meshes/xMateER7p/visual/xMatePro7_link1.stl" scale="0.001 0.001 0.001"/></geometry>
      <material name="white"/>
    </visual>
    <collision>
      <geometry><mesh filename="package://rokae_description/meshes/xMateER7p/collision/xMatePro7_link1.stl" scale="0.001 0.001 0.001"/></geometry>
    </collision>
    <inertial>      
      <mass value="5.96204"/>
      <inertia ixx="0.054" ixy="0" ixz="0" iyy="0.054" iyz="-0.007" izz="0.019"/>
      <origin rpy="0 0 0" xyz="0 -0.017 0.320"/>
    </inertial>
  </link>
  
  <joint name="joint2" type="revolute">
    <parent link="xMatePro7_link1"/>
    <child link="xMatePro7_link2"/>
    <limit effort="300" lower="-2.0933" upper="2.0933" velocity="10"/>
    <axis xyz="0 1 0"/>
    <origin rpy="0 0 0" xyz="0 0 0.404"/>
  </joint>

  <link name="xMatePro7_link2">
    <visual>
      <geometry><mesh filename="package://rokae_description/meshes/xMateER7p/visual/xMatePro7_link2.stl" scale="0.001 0.001 0.001"/></geometry>
      <material name="white"/>
    </visual>
    <collision>
      <geometry><mesh filename="package://rokae_description/meshes/xMateER7p/collision/xMatePro7_link2.stl" scale="0.001 0.001 0.001"/></geometry>
    </collision>
    <inertial>
      <mass value="5.40302"/>
      <inertia ixx="0.070" ixy="0" ixz="0" iyy="0.070" iyz="-0.014" izz="0.011"/>
      <origin rpy="0 0 0" xyz="0 0.032 0.093"/>
    </inertial>
  </link>
 
  <joint name="joint3" type="revolute">
    <parent link="xMatePro7_link2"/>
    <child link="xMatePro7_link3"/>
    <limit effort="300" lower="-3.0527" upper="3.0527" velocity="10"/>
    <axis xyz="0 0 1"/>
    <origin rpy="0 0 0" xyz="0 0 0.23743878"/>
  </joint>

  <link name="xMatePro7_link3">
    <visual>
      <geometry><mesh filename="package://rokae_description/meshes/xMateER7p/visual/xMatePro7_link3.stl" scale="0.001 0.001 0.001"/></geometry>
      <origin rpy="0 0 0" xyz="0 0 0.15549959"/>
      <material name="white"/>
    </visual>
    <collision>
      <geometry><mesh filename="package://rokae_description/meshes/xMateER7p/collision/xMatePro7_link3.stl" scale="0.001 0.001 0.001"/></geometry>
      <origin rpy="0 0 0" xyz="0 0 0.15549959"/>
    </collision>
    <inertial>    
      <mass value="3.95735"/>
      <inertia ixx="0.022" ixy="0" ixz="0" iyy="0.021" iyz="-0.002" izz="0.015"/>
      <origin rpy="0 0 0" xyz="0 -0.013 -0.067"/>
    </inertial>
  </link>
 
  <joint name="joint4" type="revolute">
    <parent link="xMatePro7_link3"/>
    <child link="xMatePro7_link4"/>
    <limit effort="300" lower="-2.0933" upper="2.0933" velocity="10"/>
    <axis xyz="0 1 0"/>
    <origin rpy="0 0 0" xyz="0 0 0.15549959"/>
  </joint>

  <link name="xMatePro7_link4">
    <visual>
      <geometry><mesh filename="package://rokae_description/meshes/xMateER7p/visual/xMatePro7_link4.stl" scale=".001 0.001 0.001"/></geometry>
      <material name="white"/>
    </visual>
    <collision>
      <geometry><mesh filename="package://rokae_description/meshes/xMateER7p/collision/xMatePro7_link4.stl" scale="0.001 0.001 0.001"/></geometry>
    </collision>
    <inertial>    
      <mass value="2.91217"/>
      <inertia ixx="0.024" ixy="0" ixz="0" iyy="0.024" iyz="-0.004" izz="0.005"/>
      <origin rpy="0 0 0" xyz="0 0.026 0.068"/>
    </inertial>
  </link>
  
  <joint name="joint5" type="revolute">
    <parent link="xMatePro7_link4"/>
    <child link="xMatePro7_link5"/>
    <limit effort="300" lower="-3.0527" upper="3.0527" velocity="10"/>
    <axis xyz="0 0 1"/>
    <origin rpy="0 0 0" xyz="0 0 0.22044633"/>
  </joint>
  
  <link name="xMatePro7_link5">
    <visual>
      <geometry><mesh filename="package://rokae_description/meshes/xMateER7p/visual/xMatePro7_link5.stl" scale="0.001 0.001 0.001"/></geometry>
      <origin rpy="0 0 0" xyz="0 0 0.14512568"/>
      <material name="white"/>
    </visual>
    <collision>
      <geometry><mesh filename="package://rokae_description/meshes/xMateER7p/collision/xMatePro7_link5.stl" scale="0.001 0.001 0.001"/></geometry>
      <origin rpy="0 0 0" xyz="0 0 0.14512568"/>
    </collision>
    <inertial>
      <mass value="2.47056"/>
      <inertia ixx="0.019" ixy="0" ixz="0" iyy="0.018" iyz="-0.002" izz="0.010"/>
      <origin rpy="0 0 0" xyz="0 -0.014 -0.079"/>
    </inertial>
  </link>
  
  <joint name="joint6" type="revolute">
    <parent link="xMatePro7_link5"/>
    <child link="xMatePro7_link6"/>
    <limit effort="300" lower="-2.0933" upper="2.0933" velocity="10"/>
    <axis xyz="0 1 0"/>
    <origin rpy="0.0 0.0 0" xyz="0 0 0.14512568" />
  </joint>
  
  <link name="xMatePro7_link6">
    <visual>
      <geometry><mesh filename="package://rokae_description/meshes/xMateER7p/visual/xMatePro7_link6.stl" scale="0.001 0.001 0.001"/></geometry>
    </visual>
    <collision>
      <geometry><mesh filename="package://rokae_description/meshes/xMateER7p/collision/xMatePro7_link6.stl" scale="0.001 0.001 0.001"/></geometry>
    </collision>
    <inertial>
      <mass value="2.16053"/>
      <inertia ixx="0.016" ixy="0" ixz="0" iyy="0.016" iyz="-0.003" izz="0.003"/>
      <origin rpy="0 0 0" xyz="0 0.020 0.085"/>
    </inertial>
  </link>

  <joint name="joint7" type="revolute">
    <parent link="xMatePro7_link6"/>
    <child link="xMatePro7_link7"/>
    <limit effort="300" lower="-6.283" upper="6.283" velocity="10"/>
    <axis xyz="0 0 1"/>
    <origin rpy="0.0 0.0 0.0" xyz="0 0 0.25090877" />
  </joint>
  
  <link name="xMatePro7_link7">
    <visual>
      <geometry><mesh filename="package://rokae_description/meshes/xMateER7p/visual/xMatePro7_link7.stl" scale="0.001 0.001 0.001"/></geometry>
    </visual>
    <collision>
      <geometry><mesh filename="package://rokae_description/meshes/xMateER7p/collision/xMatePro7_link7.stl" scale="0.001 0.001 0.001"/></geometry>
    </collision>
    <inertial>
      <mass value="1.26834"/>
      <inertia ixx="0.002" ixy="-0.0" ixz="-0.0" iyy="0.001" iyz="-0.0" izz="0.002"/>
      <origin rpy="0 0 0" xyz="0 0.012 -0.052"/>
    </inertial>
  </link>
  
</robot>